<?xml version="1.0" encoding="utf-8"?>
<!-- This URDF was automatically created by SolidWorks to URDF Exporter! Originally created by Stephen Brawner (brawner@gmail.com) 
     Commit Version: 1.6.0-1-g15f4949  Build Version: 1.6.7594.29634
     For more information, please see http://wiki.ros.org/sw_urdf_exporter -->
<robot
  name="snake_robot_temp">
  <link
    name="head_link">
    <inertial>
      <origin
        xyz="-7.37810372423381E-08 -0.0107815300539941 0.00412052567157211"
        rpy="0 0 0" />
      <mass
        value="0.169319636058232" />
      <inertia
        ixx="0.000126397990407614"
        ixy="2.78872180246068E-10"
        ixz="3.16596245516813E-11"
        iyy="7.32432228818471E-05"
        iyz="-2.05002419136773E-05"
        izz="0.000128044781657033" />
    </inertial>
    <visual>
      <origin
        xyz="0 0 0"
        rpy="0 0 0" />
      <geometry>
        <mesh
          filename="package://snake_robot_temp/meshes/head_link.STL" />
      </geometry>
      <material
        name="">
        <color
          rgba="0.792156862745098 0.819607843137255 0.933333333333333 1" />
      </material>
    </visual>
    <collision>
      <origin
        xyz="0 0 0"
        rpy="0 0 0" />
      <geometry>
        <mesh
          filename="package://snake_robot_temp/meshes/head_link.STL" />
      </geometry>
    </collision>
  </link>
  <link
    name="coupling_1">
    <inertial>
      <origin
        xyz="0.00484148879238799 0.0300000000884499 0.00484155803317407"
        rpy="0 0 0" />
      <mass
        value="0.143657629703553" />
      <inertia
        ixx="0.000132610817812716"
        ixy="2.00281059414306E-05"
        ixz="3.36773246546473E-06"
        iyy="5.72345263715008E-05"
        iyz="-2.00281685250379E-05"
        izz="0.00013260539027947" />
    </inertial>
    <visual>
      <origin
        xyz="0 0 0"
        rpy="0 0 0" />
      <geometry>
        <mesh
          filename="package://snake_robot_temp/meshes/coupling_1.STL" />
      </geometry>
      <material
        name="">
        <color
          rgba="0.372549019607843 0.533333333333333 1 1" />
      </material>
    </visual>
    <collision>
      <origin
        xyz="0 0 0"
        rpy="0 0 0" />
      <geometry>
        <mesh
          filename="package://snake_robot_temp/meshes/coupling_1.STL" />
      </geometry>
    </collision>
  </link>
  <joint
    name="coupling_1_joint"
    type="revolute">
    <origin
      xyz="0 0 0.02"
      rpy="1.5708 0 1.5708" />
    <parent
      link="head_link" />
    <child
      link="coupling_1" />
    <axis
      xyz="1 0 0" />
    <limit
      lower="-1.0472"
      upper="1.0472"
      effort="0"
      velocity="0" />
  </joint>
</robot>